Workbook

Sheet Avance Financiero
A1: Cuenta Número 10000892 (Informe ejecución y rendimientos)
A2: Cuenta ahorros | B2: Fecha | C2: (+) Depositos (Gobernación de Antioquia) | D2: SALDO INICIAL | E2: (+) Rendimientos | F2: (-) Retiros por reintegro rendimientos | G2: (-) Ejecucion Convenio (Pagos Contrato Delegado) | I2: (-) Total Retiros | J2: SALDO FINAL
G3: Contigo Antioquia | H3: Otrosí - CRUE
A4: 100015699 | B4: 45594 | C4: 5000000000 | D4: 0 | E4: =+'EJecucion convenio 46000017482'!E60 -> 487902 | F4: 0 | G4: 0 | H4: 0 | I4: =SUM(F4:G4) -> 0 | J4: =D4+C4-I4+E4 -> 5000487902
A5: 100015699 | B5: 45626 | C5: 0 | D5: =J4 -> 5000487902 | E5: =+'EJecucion convenio 46000017482'!E61 -> 7277516 | F5: 0 | G5: 0 | H5: 0 | I5: =SUM(F5:G5) -> 0 | J5: =D5+C5-I5+E5 -> 5007765418
A6: 100015700 | B6: 45626 | C6: 0 | D6: =J5 -> 5007765418 | E6: =+'EJecucion convenio 46000017482'!E62 -> 5486 | F6: 0 | G6: 0 | H6: 0 | I6: =SUM(F6:G6) -> 0 | J6: =D6+C6-I6+E6 -> 5007770904
A7: 100015699 | B7: 45657 | C7: 0 | D7: =J6 -> 5007770904 | E7: =+'EJecucion convenio 46000017482'!E63 -> 7417358 | F7: 0 | G7: 0 | H7: 0 | I7: =SUM(F7:G7) -> 0 | J7: =D7+C7-I7+E7 -> 5015188262
A8: 100015700 | B8: 45657 | C8: 0 | D8: =J7 -> 5015188262 | E8: =+'EJecucion convenio 46000017482'!E64 -> 16571 | F8: 0 | G8: 0 | H8: 0 | I8: =SUM(F8:G8) -> 0 | J8: =D8+C8-I8+E8 -> 5015204833
A9: 100015699 | B9: 45688 | C9: 0 | D9: =J8 -> 5015204833 | E9: =+'EJecucion convenio 46000017482'!E65 -> 7422793 | F9: 0 | G9: 0 | H9: 0 | I9: =SUM(F9:G9) -> 0 | J9: =D9+C9-I9+E9 -> 5022627626
A10: 100015700 | B10: 45688 | C10: 0 | D10: =J9 -> 5022627626 | E10: =+'EJecucion convenio 46000017482'!E66 -> 27625 | F10: 0 | G10: 0 | H10: 0 | I10: =SUM(F10:G10) -> 0 | J10: =D10+C10-I10+E10 -> 5022655251
A11: 100015699 | B11: 45716 | C11: 0 | D11: =J10 -> 5022655251 | E11: =+'EJecucion convenio 46000017482'!E67 -> 6722333 | F11: 0 | G11: 0 | H11: 0 | I11: 0 | J11: =D11+C11-I11+E11 -> 5029377584
A12: 100015700 | B12: 45716 | C12: 0 | D12: =J11 -> 5029377584 | E12: =+'EJecucion convenio 46000017482'!E68 -> 34605 | F12: 0 | G12: 0 | H12: 0 | I12: =SUM(F12:G12) -> 0 | J12: =D12+C12-I12+E12 -> 5029412189
A13: 100015699 | B13: 45747 | C13: 0 | D13: =J12 -> 5029412189 | E13: =+'EJecucion convenio 46000017482'!E69 -> 7460534 | F13: 0 | G13: 0 | H13: 0 | I13: =SUM(F13:G13) -> 0 | J13: =D13+C13-I13+E13 -> 5036872723
A14: 100015700 | B14: 45747 | C14: 0 | D14: =J13 -> 5036872723 | E14: =+'EJecucion convenio 46000017482'!E70 -> 48968 | F14: 0 | G14: 0 | H14: 0 | I14: =SUM(F14:G14) -> 0 | J14: =D14+C14-I14+E14 -> 5036921691
A15: 100015699 | B15: 31/04/2025 | C15: 0 | D15: =J14 -> 5036921691 | E15: =+'EJecucion convenio 46000017482'!E71 -> 7156542 | F15: 0 | G15: 0 | H15: 0 | I15: =SUM(F15:G15) -> 0 | J15: =D15+C15-I15+E15 -> 5044078233
A16: 100015700 | B16: 31/04/2025 | C16: 0 | D16: =J15 -> 5044078233 | E16: =+'EJecucion convenio 46000017482'!E72 -> 57503 | F16: 0 | G16: 0 | H16: 0 | I16: =SUM(F16:G16) -> 0 | J16: =D16+C16-I16+E16 -> 5044135736
A17: 100015699 100015700 | B17: 45807 | C17: 0 | D17: =J16 -> 5044135736 | E17: 0 | F17: =+'EJecucion convenio 46000017482'!E122 -> 44135736 | G17: 0 | H17: 0 | I17: =SUM(F17:G17) -> 44135736 | J17: =D17+C17-I17+E17 -> 5000000000
A18: 100015699 | B18: 45808 | C18: 0 | D18: =J17 -> 5000000000 | E18: =+'EJecucion convenio 46000017482'!E73 -> 7274207 | F18: 0 | G18: 0 | H18: 0 | I18: =SUM(F18:G18) -> 0 | J18: =D18+C18-I18+E18 -> 5007274207
A19: 100015700 | B19: 45808 | C19: 0 | D19: =J18 -> 5007274207 | E19: =+'EJecucion convenio 46000017482'!E74 -> 62943 | F19: 0 | G19: 0 | H19: 0 | I19: =SUM(F19:G19) -> 0 | J19: =D19+C19-I19+E19 -> 5007337150
A20: 100015699 100015700 | B20: 45820 | C20: 0 | D20: =J19 -> 5007337150 | E20: 0 | F20: 7337150 | G20: 0 | H20: 0 | I20: =SUM(F20:G20) -> 7337150 | J20: =D20+C20-I20+E20 -> 5000000000
A21: 100015699 | B21: 45838 | C21: 0 | D21: =J20 -> 5000000000 | E21: =+'EJecucion convenio 46000017482'!E75 -> 6955975 | F21: 0 | G21: 0 | H21: 0 | I21: =SUM(F21:G21) -> 0 | J21: =D21+C21-I21+E21 -> 5006955975
A22: 100015700 | B22: 45838 | C22: 0 | D22: =J21 -> 5006955975 | E22: =+'EJecucion convenio 46000017482'!E76 -> 7390 | F22: 0 | G22: 0 | H22: 0 | I22: =SUM(F22:G22) -> 0 | J22: =D22+C22-I22+E22 -> 5006963365
A23: 100015699 100015700 | B23: 45861 | C23: 0 | D23: =J22 -> 5006963365 | E23: 0 | F23: =+'EJecucion convenio 46000017482'!E124 -> 6963365 | G23: 0 | H23: 0 | I23: =SUM(F23:G23) -> 6963365 | J23: =D23+C23-I23+E23 -> 5000000000
A24: 100015699 | B24: 45869 | C24: 0 | D24: =J23 -> 5000000000 | E24: =+'EJecucion convenio 46000017482'!E77 -> 7212374 | F24: 0 | G24: 0 | H24: 0 | I24: =SUM(F24:G24) -> 0 | J24: =D24+C24-I24+E24 -> 5007212374
A25: 100015700 | B25: 45869 | C25: 0 | D25: =J24 -> 5007212374 | E25: =+'EJecucion convenio 46000017482'!E78 -> 11633 | F25: 0 | G25: 0 | H25: 0 | I25: =SUM(F25:G25) -> 0 | J25: =D25+C25-I25+E25 -> 5007224007
A26: 100015699 | B26: 45881 | C26: 0 | D26: =J25 -> 5007224007 | E26: 0 | F26: 0 | G26: 2200000000 | H26: 0 | I26: =SUM(F26:G26) -> 2200000000 | J26: =D26+C26-I26+E26 -> 2807224007
A27: 100015699 100015700 | B27: 45884 | C27: 0 | D27: =J26 -> 2807224007 | E27: 0 | F27: 7224007 | G27: 0 | H27: 0 | I27: =SUM(F27:G27) -> 7224007 | J27: =D27+C27-I27+E27 -> 2800000000
A28: =+'EJecucion convenio 46000017482'!A79 -> 100015699 | B28: =IF('EJecucion convenio 46000017482'!C79="","",'EJecucion convenio 46000017482'!C79) -> 45900 | C28: 0 | D28: =J27 -> 2800000000 | E28: =+'EJecucion convenio 46000017482'!E79 -> 6016060 | F28: 0 | G28: 0 | H28: 0 | I28: =SUM(F28:G28) -> 0 | J28: =D28+C28-I28+E28 -> 2806016060
A29: =+'EJecucion convenio 46000017482'!A80 -> 100015700 | B29: =IF('EJecucion convenio 46000017482'!C80="","",'EJecucion convenio 46000017482'!C80) -> 45900 | C29: 0 | D29: =J28 -> 2806016060 | E29: =+'EJecucion convenio 46000017482'!E80 -> 9042 | F29: 0 | G29: 0 | H29: 0 | I29: =SUM(F29:G29) -> 0 | J29: =D29+C29-I29+E29 -> 2806025102
A30: 100015699 100015700 | B30: 45922 | C30: 0 | D30: =J29 -> 2806025102 | E30: 0 | F30: 6025102 | G30: 0 | H30: 0 | I30: =SUM(F30:G30) -> 6025102 | J30: =D30+C30-I30+E30 -> 2800000000
A31: 100015699 | B31: 45925 | C31: 0 | D31: =J30 -> 2800000000 | E31: 0 | F31: 0 | G31: 998095000 | H31: 0 | I31: =SUM(F31:G31) -> 998095000 | J31: =D31+C31-I31+E31 -> 1801905000
A32: 100015699 | B32: 45925 | C32: 0 | D32: =J31 -> 1801905000 | E32: 0 | F32: 0 | G32: 190754739 | H32: 0 | I32: =SUM(F32:G32) -> 190754739 | J32: =D32+C32-I32+E32 -> 1611150261
A33: =+'EJecucion convenio 46000017482'!A81 -> 100015699 | B33: =IF('EJecucion convenio 46000017482'!C81="","",'EJecucion convenio 46000017482'!C81) -> 45930 | C33: 0 | D33: =J32 -> 1611150261 | E33: =+'EJecucion convenio 46000017482'!E81 -> 3507390 | F33: 0 | G33: 0 | H33: 0 | I33: =SUM(F33:G33) -> 0 | J33: =D33+C33-I33+E33 -> 1614657651
A34: =+'EJecucion convenio 46000017482'!A82 -> 100015700 | B34: =IF('EJecucion convenio 46000017482'!C82="","",'EJecucion convenio 46000017482'!C82) -> 45930 | C34: 0 | D34: =J33 -> 1614657651 | E34: =+'EJecucion convenio 46000017482'!E82 -> 7347 | F34: 0 | G34: 0 | H34: 0 | I34: =SUM(F34:G34) -> 0 | J34: =D34+C34-I34+E34 -> 1614664998
A35: 100015699 100015700 | B35: 45937 | C35: 0 | D35: =J34 -> 1614664998 | E35: 0 | F35: 3514737 | G35: 0 | H35: 0 | I35: =SUM(F35:G35) -> 3514737 | J35: =D35+C35-I35+E35 -> 1611150261
A36: 100015699 | B36: 45954 | C36: 0 | D36: =J35 -> 1611150261 | E36: 0 | F36: 0 | G36: 13650000 | H36: 0 | I36: =SUM(F36:G36) -> 13650000 | J36: =D36+C36-I36+E36 -> 1597500261
A37: 100015699 | B37: 45954 | C37: 0 | D37: =J36 -> 1597500261 | E37: 0 | F37: 0 | G37: 95018644 | H37: 0 | I37: =SUM(F37:G37) -> 95018644 | J37: =D37+C37-I37+E37 -> 1502481617
A38: 100015699 | B38: 45954 | C38: 0 | D38: =J37 -> 1502481617 | E38: =+'EJecucion convenio 46000017482'!E93 -> 281635 | F38: 0 | G38: 730635725 | H38: 0 | I38: =SUM(F38:G38) -> 730635725 | J38: =D38+C38-I38+E38 -> 772127527
A39: 100015699 | B39: 45954 | C39: 0 | D39: =J38 -> 772127527 | E39: =+'EJecucion convenio 46000017482'!E94 -> 5510 | F39: 0 | G39: 211478886 | H39: 0 | I39: =SUM(F39:G39) -> 211478886 | J39: =D39+C39-I39+E39 -> 560654151
A40: =+'EJecucion convenio 46000017482'!A88 -> 100015700 | B40: 45961 | C40: 0 | D40: =J39 -> 560654151 | E40: 2120535 | F40: 0 | H40: 0 | I40: =SUM(F40:G40) -> 0 | J40: =D40+C40-I40+E40 -> 562774686
...

Sheet EJecucion convenio 46000017482
A2: Convenio: 4600017482/0231 de 2024
A3: Objeto: | B3: "Aunar esfuerzos en la constitución de un fondo especial de recursos, para Implementar estrategias para la transformación digital en el Departamento de Antioquia – Secretaría Seccional de Salud y Protección Social."
A4: Fecha de Suscripcion: | B4: 45582 | C4: Fecha de Inicio: | D4: 45589
A5: Plazo: | B5: Meses | C5: 39 | D5: Días | E5: =+C5*30 -> 1170
A6: Fecha de Terminación: | B6: 46752
A7: Otrosí 1: | B7: 46020
A8: Adición de recursos: | B8: 1462022598
A9: Disponibilidad Presupuestal
A10: FECHA CREACIÓN | B10: VIGENCIA | C10: VALOR | D10: RESPALDO PRESUPUESTAL
A11: 44918 | B11: 2024 | C11: 5000000000 | D11: CDP 3500054749
A12: 44918 | B12: 2025 | C12: 1500000000 | D12: Certificado de vigencia futura No. 6000003088
A13: 44918 | B13: 2025 | C13: 1500000000 | D13: Certificado de vigencia futura No. 6000003093
A14: 44918 | B14: 2025 | C14: 1500000000 | D14: Certificado de vigencia futura No. 6000003098
A15: 44918 | B15: 2025 | C15: 1500000000 | D15: Certificado de vigencia futura No. 6000003103
A16: 44918 | B16: 2026 | C16: 1750000000 | D16: Certificado de vigencia futura No. 6000003089
A17: 44918 | B17: 2026 | C17: 1750000000 | D17: Certificado de vigencia futura No. 6000003094
A18: 44918 | B18: 2026 | C18: 1750000000 | D18: Certificado de vigencia futura No. 6000003099
A19: 44918 | B19: 2026 | C19: 1750000000 | D19: Certificado de vigencia futura No. 6000003104 | K19: 27568325
A20: 44918 | B20: 2027 | C20: 2000000000 | D20: Certificado de vigencia futura No. 6000003090 | K20: 16130869
A21: 44918 | B21: 2027 | C21: 2000000000 | D21: Certificado de vigencia futura No. 6000003095 | K21: 4358895
A22: 44918 | B22: 2027 | C22: 2000000000 | D22: Certificado de vigencia futura No. 6000003100 | K22: 45786710
A23: 44918 | B23: 2027 | C23: 2000000000 | D23: Certificado de vigencia futura No. 6000003105 | K23: 48935567
J24: 207173258 | K24: =SUM(K19:K23) -> 142780366 | L24: =+J24-K24 -> 64392892
A27: Supervisor: | B27: David Fernando Arisitizábal Serna | D27: Identificación | E27: 71740628
A28: Dependencia: | B28: Secretaría de Salud e Inclusión Social | D28: Fuente de Financiación: | E28: Transformación Digital en Salud
A29: Encargo fiduciario | B29: 10000892
B30: Cuenta encargo | C30: 100015699 | D30: Cuenta rendimientos | E30: 100015700
A31: Banco: | B31: IDEA | D31: Estado cuenta: | E31: Activa
A33: VALOR CONVENIO
A34: Aportantes | B34: Aportes totales | C34: Gobernación de Antioquia Secretaría de Salud e Inclusión social | D34: IDEA Costos operativos (Aportes en especie)
A35: Aporte total | B35: =+C35+D35 -> 27300000000 | C35: 26000000000 | D35: 1300000000
A36: Totales % | B36: =C36+D36 -> 1 | C36: =+C35/$B$35 -> 0.95238095 | D36: =+D35/$B$35 -> 0.047619048
A37: Aporte total (recursos liquidos) | B37: =+C35 -> 26000000000 | C37: =SUM(C34:C35) -> 26000000000 | D37: =SUM(D34:D35) -> 1300000000
A38: Subtotales % | B38: =C38+D38 -> 1 | C38: =+C37/B35 -> 0.95238095 | D38: =+D37/$B$35 -> 0.047619048
A39: TOTAL VALOR DEL CONVENIO | B39: =+C35+D35 -> 27300000000
A41: APORTES REALIZADOS
A42: Documento - Fecha | B42: Fecha de Consiganción | C42: Valor | D42: Gobernación de Antioquia Secretaría de Salud e Inclusión social | E42: IDEA Costos operativos (Aportes en especie)
A43: 4300126000 | B43: 45594 | C43: 5000000000 | D43: =+C43 -> 5000000000 | E43: 0
A44: Acta de inicio 24/10/2024 | B44: 45594 | C44: 1300000000 | D44: 0 | E44: =+C44 -> 1300000000
A45: 4300131771 | B45: 46007 | C45: 6000000000 | D45: =+C45 -> 6000000000 | E45: 0
...

Sheet Ejecución financiera CAS
B1: Ejecución Recursos Contigo Antioquia: Secrataría de Salud e Inclusión Social
B2: Fecha | C2: Componente | F2: Recursos comprometidos | O2: =+O9+O10+O11+O12+7000000000 -> 18815817845
B3: 45757 | C3: Contigo Antioquia Salud - CAS | F3: 25982939387 | O3: =+O2+O36 -> 20188918975
B4: 46020 | C4: Contigo Antioquia Salud - CRUE | F4: 1462022598
B7: Valor Total Contrato | F7: =SUM(F3:G4) -> 27444961985 | I7: Ejecución de Recursos Transferidos al IDEA | N7: Recursos Transferidos al IDEA
B8: Componente | C8: Fecha | D8: Soporte | E8: Ejecución Financiera Valor + | G8: Sin ejecución | I8: Fecha | J8: Ejecución Financiera Valor + | L8: Sin ejecución | N8: Fecha | O8: Valor Transferido IDEA | Q8: Componente
A9: =IF(C9="","",ROW()-8) -> 1 | B9: CAS | C9: 12/08/2025 | D9: Factura V1460 | E9: 2200000000 | F9: =+SUM(E9:E75)/$F$7 -> 0.54312004 | G9: =IF(E9=0,0,F3-E9) -> 23782939387 | I9: =IF(C9="","",+C9) -> 12/08/2025 | J9: =+E9 -> 2200000000 | K9: =SUM(J9:J75)/O34 -> 0.96995397 | L9: =IF(J9=0,"",O34-J9) -> 13167645700 | N9: 45594 | O9: 5000000000 | P9: =+O34/F7 -> 0.55994414 | Q9: CAS
A10: =IF(C10="","",ROW()-8) -> 2 | B10: CAS | C10: 02/09/2025 | D10: Cuanta de Cobro 229 | E10: 998095000 | G10: =IF(E10=0,0,G9-E10) -> 22784844387 | I10: =IF(C10="","",+C10) -> 02/09/2025 | J10: =+E10 -> 998095000 | L10: =IF(J10=0,"",L9-J10) -> 12169550700 | N10: 46001 | O10: 6000000000 | Q10: CAS
A11: =IF(C11="","",ROW()-8) -> 3 | B11: CAS | C11: 16/09/2025 | D11: Factura V1519 | E11: 190754739 | G11: =IF(E11=0,0,G10-E11) -> 22594089648 | I11: =IF(C11="","",+C11) -> 16/09/2025 | J11: =+E11 -> 190754739 | L11: =IF(J11=0,"",L10-J11) -> 11978795961 | N11: 46044 | O11: 207173258 | Q11: CRUE | R11: 7000000000
A12: =IF(C12="","",ROW()-8) -> 4 | B12: CAS | C12: 23/10/2025 | D12: Cuanta de Cobro 259 | E12: 13650000 | G12: =IF(E12=0,0,G11-E12) -> 22580439648 | I12: =IF(C12="","",+C12) -> 23/10/2025 | J12: =+E12 -> 13650000 | L12: =IF(J12=0,"",L11-J12) -> 11965145961 | N12: 46101 | O12: 608644587 | Q12: CRUE
A13: =IF(C13="","",ROW()-8) -> 5 | B13: CAS | C13: 23/10/2025 | D13: Cuanta de Cobro 261 | E13: 95018644 | G13: =IF(E13=0,0,G12-E13) -> 22485421004 | I13: =IF(C13="","",+C13) -> 23/10/2025 | J13: =+E13 -> 95018644 | L13: =IF(J13=0,"",L12-J13) -> 11870127317 | N13: 46171 | O13: 1817086974 | Q13: CAS | R13: =SUM(O13:O20) -> 3551827855
A14: =IF(C14="","",ROW()-8) -> 6 | B14: CAS | C14: 23/10/2025 | D14: Factura V1554 | E14: 730635725 | G14: =IF(E14=0,0,G13-E14) -> 21754785279 | I14: =IF(C14="","",+C14) -> 23/10/2025 | J14: =+E14 -> 730635725 | L14: =IF(J14=0,"",L13-J14) -> 11139491592 | N14: 46191 | O14: 526978224 | Q14: CAS
A15: =IF(C15="","",ROW()-8) -> 7 | B15: CAS | C15: 23/10/2025 | D15: Factura V1561 | E15: 211478886 | G15: =IF(E15=0,0,G14-E15) -> 21543306393 | I15: =IF(C15="","",+C15) -> 23/10/2025 | J15: =+E15 -> 211478886 | L15: =IF(J15=0,"",L14-J15) -> 10928012706 | N15: 46220 | O15: 526978224 | Q15: CAS | R15: =+R11-R13 -> 3448172145
A16: =IF(C16="","",ROW()-8) -> 8 | B16: CAS | C16: 25/11/2025 | D16: Factura V1598 | E16: 70856001 | G16: =IF(E16=0,0,G15-E16) -> 21472450392 | I16: =IF(C16="","",+C16) -> 25/11/2025 | J16: =+E16 -> 70856001 | L16: =IF(J16=0,"",L15-J16) -> 10857156705 | O16: 680784433 | Q16: CAS
A17: =IF(C17="","",ROW()-8) -> 9 | B17: CAS | C17: 25/11/2025 | D17: Factura V1600 | E17: 364100919 | G17: =IF(E17=0,0,G16-E17) -> 21108349473 | I17: =IF(C17="","",+C17) -> 25/11/2025 | J17: =+E17 -> 364100919 | L17: =IF(J17=0,"",L16-J17) -> 10493055786
A18: =IF(C18="","",ROW()-8) -> 10 | B18: CAS | C18: 25/11/2025 | D18: Cuenta de Cobro 291 | E18: 13650000 | G18: =IF(E18=0,0,G17-E18) -> 21094699473 | I18: =IF(C18="","",+C18) -> 25/11/2025 | J18: =+E18 -> 13650000 | L18: =IF(J18=0,"",L17-J18) -> 10479405786 | R18: =+O13+O14 -> 2344065198
A19: =IF(C19="","",ROW()-8) -> 11 | B19: CAS | C19: 02/12/2025 | D19: Cuenta de Cobro 320 | E19: 13650000 | G19: =IF(E19=0,0,G18-E19) -> 21081049473 | I19: =IF(C19="","",+C19) -> 02/12/2025 | J19: =+E19 -> 13650000 | L19: =IF(J19=0,"",L18-J19) -> 10465755786 | R19: =+R11-R18 -> 4655934802
A20: =IF(C20="","",ROW()-8) -> 12 | B20: CAS | C20: 02/12/2025 | D20: Cuenta de Cobro 321 | E20: 1095953586 | G20: =IF(E20=0,0,G19-E20) -> 19985095887 | I20: =IF(C20="","",+C20) -> 02/12/2025 | J20: =+E20 -> 1095953586 | L20: =IF(J20=0,"",L19-J20) -> 9369802200 | R20: 4441000000
A21: =IF(C21="","",ROW()-8) -> 13 | B21: CAS | C21: 03/12/2025 | D21: Factura V1633 | E21: 1299480 | G21: =IF(E21=0,0,G20-E21) -> 19983796407 | I21: =IF(C21="","",+C21) -> 03/12/2025 | J21: =+E21 -> 1299480 | L21: =IF(J21=0,"",L20-J21) -> 9368502720 | R21: =+R19-R20 -> 214934802
A22: =IF(C22="","",ROW()-8) -> 14 | B22: CAS | C22: 03/12/2025 | D22: Factura V1634 | E22: 262400529 | G22: =IF(E22=0,0,G21-E22) -> 19721395878 | I22: =IF(C22="","",+C22) -> 03/12/2025 | J22: =+E22 -> 262400529 | L22: =IF(J22=0,"",L21-J22) -> 9106102191
A23: =IF(C23="","",ROW()-8) -> 15 | B23: CAS | C23: 16/01/2026 | D23: Cuenta de Cobro 378 | E23: 1539588229 | G23: =IF(E23=0,0,G22+F4-E23) -> 19643830247 | I23: =IF(C23="","",+C23) -> 16/01/2026 | J23: =+E23 -> 1539588229 | L23: =IF(J23=0,"",L22-J23) -> 7566513962
A24: =IF(C24="","",ROW()-8) -> 16 | B24: CAS | C24: 19/01/2026 | D24: Factura V1741 | E24: 105634262 | G24: =IF(E24=0,0,G23-E24) -> 19538195985 | I24: =IF(C24="","",+C24) -> 19/01/2026 | J24: =+E24 -> 105634262 | L24: =IF(J24=0,"",L23-J24) -> 7460879700
A25: =IF(C25="","",ROW()-8) -> 17 | B25: CAS | C25: 19/01/2026 | D25: Factura V1740 | E25: 378854365 | G25: =IF(E25=0,0,G24-E25) -> 19159341620 | I25: =IF(C25="","",+C25) -> 19/01/2026 | J25: =+E25 -> 378854365 | L25: =IF(J25=0,"",L24-J25) -> 7082025335
A26: =IF(C26="","",ROW()-8) -> 18 | B26: CAS | C26: 16/01/2026 | D26: Cuenta de cobro 377 | E26: 13650000 | G26: =IF(E26=0,0,G25-E26) -> 19145691620 | I26: =IF(C26="","",+C26) -> 16/01/2026 | J26: =+E26 -> 13650000 | L26: =IF(J26=0,"",L25-J26) -> 7068375335
A27: =IF(C27="","",ROW()-8) -> 19 | B27: CAS | C27: 10/02/2026 | D27: Factura V1756 | E27: 1157936725 | G27: =IF(E27=0,0,G26-E27) -> 17987754895 | I27: =IF(C27="","",+C27) -> 10/02/2026 | J27: =+E27 -> 1157936725 | L27: =IF(J27=0,"",L26-J27) -> 5910438610
A28: =IF(C28="","",ROW()-8) -> 20 | B28: CAS | C28: 10/02/2026 | D28: Factura V1757 | E28: 147868279 | G28: =IF(E28=0,0,G27-E28) -> 17839886616 | I28: =IF(C28="","",+C28) -> 10/02/2026 | J28: =+E28 -> 147868279 | L28: =IF(J28=0,"",L27-J28) -> 5762570331
A29: =IF(C29="","",ROW()-8) -> 21 | B29: CAS | C29: 10/02/2026 | D29: Cuenta de cobro 384 | E29: 13991250 | G29: =IF(E29=0,0,G28-E29) -> 17825895366 | I29: =IF(C29="","",+C29) -> 10/02/2026 | J29: =+E29 -> 13991250 | L29: =IF(J29=0,"",L28-J29) -> 5748579081
A30: =IF(C30="","",ROW()-8) -> 22 | B30: CAS | C30: 10/03/2026 | D30: Cuenta de cobro 400 | E30: 13991250 | G30: =IF(E30=0,0,G29-E30) -> 17811904116 | I30: =IF(C30="","",+C30) -> 10/03/2026 | J30: =+E30 -> 13991250 | L30: =IF(J30=0,"",L29-J30) -> 5734587831
A31: =IF(C31="","",ROW()-8) -> 23 | B31: CAS | C31: 11/03/2026 | D31: Factura V1808 | E31: 1331967 | G31: =IF(E31=0,0,G30-E31) -> 17810572149 | I31: =IF(C31="","",+C31) -> 11/03/2026 | J31: =+E31 -> 1331967 | L31: =IF(J31=0,"",L30-J31) -> 5733255864
A32: =IF(C32="","",ROW()-8) -> 24 | B32: CAS | C32: 11/03/2026 | D32: Factura V1809 | E32: 370527663 | G32: =IF(E32=0,0,G31-E32) -> 17440044486 | I32: =IF(C32="","",+C32) -> 11/03/2026 | J32: =+E32 -> 370527663 | L32: =IF(J32=0,"",L31-J32) -> 5362728201
A33: =IF(C33="","",ROW()-8) -> 25 | B33: CRUE | C33: 46128 | D33: Cuenta de cobro 419 | E33: 27568325 | G33: =IF(E33=0,0,G32-E33) -> 17412476161 | I33: =IF(C33="","",+C33) -> 46128 | J33: =+E33 -> 27568325 | L33: =IF(J33=0,"",L32-J33) -> 5335159876
A34: =IF(C34="","",ROW()-8) -> 26 | B34: CAS | C34: 46128 | D34: Cuenta de cobro 420 | E34: 13991250 | G34: =IF(E34=0,0,G33-E34) -> 17398484911 | I34: =IF(C34="","",+C34) -> 46128 | J34: =+E34 -> 13991250 | L34: =IF(J34=0,"",L33-J34) -> 5321168626 | N34: Total Recursos | O34: =SUM(O9:O33) -> 15367645700 | P34: =1-P9 -> 0.44005586 | Q34: =+F81+F83-O34 -> 12094376898
A35: =IF(C35="","",ROW()-8) -> 27 | B35: CRUE | C35: 46129 | D35: Cuenta de cobro 421 | E35: 141873578 | G35: =IF(E35=0,0,G34-E35) -> 17256611333 | I35: =IF(C35="","",+C35) -> 46129 | J35: =+E35 -> 141873578 | L35: =IF(J35=0,"",L34-J35) -> 5179295048
A36: =IF(C36="","",ROW()-8) -> 28 | B36: CAS | C36: 46129 | D36: Factura V1851 | E36: 979376728 | G36: =IF(E36=0,0,G35-E36) -> 16277234605 | I36: =IF(C36="","",+C36) -> 46129 | J36: =+E36 -> 979376728 | L36: =IF(J36=0,"",L35-J36) -> 4199918320 | O36: 1373101130
A37: =IF(C37="","",ROW()-8) -> 29 | B37: CAS | C37: 46129 | D37: Factura V1852 | E37: 1331967 | G37: =IF(E37=0,0,G36-E37) -> 16275902638 | I37: =IF(C37="","",+C37) -> 46129 | J37: =+E37 -> 1331967 | L37: =IF(J37=0,"",L36-J37) -> 4198586353
A38: =IF(C38="","",ROW()-8) -> 30 | B38: CRUE | C38: 46183 | D38: Cuenta de cobro 443 | E38: 45786710 | G38: =IF(E38=0,0,G37-E38) -> 16230115928 | I38: =IF(C38="","",+C38) -> 46183 | J38: =+E38 -> 45786710 | L38: =IF(J38=0,"",L37-J38) -> 4152799643 | O38: =+O34+O36 -> 16740746830
A39: =IF(C39="","",ROW()-8) -> 31 | B39: CRUE | C39: 46184 | D39: Factura V1938 | E39: 16130869 | G39: =IF(E39=0,0,G38-E39) -> 16213985059 | I39: =IF(C39="","",+C39) -> 46184 | J39: =+E39 -> 16130869 | L39: =IF(J39=0,"",L38-J39) -> 4136668774 | Q39: 98110087
A40: =IF(C40="","",ROW()-8) -> 32 | B40: CRUE | C40: 46183 | D40: Cuenta de cobro 448 | E40: 48935567 | G40: =IF(E40=0,0,G39-E40) -> 16165049492 | I40: =IF(C40="","",+C40) -> 46183 | J40: =+E40 -> 48935567 | L40: =IF(J40=0,"",L39-J40) -> 4087733207 | O40: 14721267575 | Q40: 164290442
A41: =IF(C41="","",ROW()-8) -> 33 | B41: CRUE | C41: 46184 | D41: Factura V1941 | E41: 4358895 | G41: =IF(E41=0,0,G40-E41) -> 16160690597 | I41: =IF(C41="","",+C41) -> 46184 | J41: =+E41 -> 4358895 | L41: =IF(J41=0,"",L40-J41) -> 4083374312 | Q41: =SUM(Q39:Q40) -> 262400529
A42: =IF(C42="","",ROW()-8) -> 34 | B42: CAS | C42: 46183 | D42: Cuenta de cobro 444 | E42: 13991250 | G42: =IF(E42=0,0,G41-E42) -> 16146699347 | I42: =IF(C42="","",+C42) -> 46183 | J42: =+E42 -> 13991250 | L42: =IF(J42=0,"",L41-J42) -> 4069383062 | O42: =+O40-O34 -> -646378125
...

Sheet % Ejecución financiera CRUE
B1: Ejecución Recursos Contigo Antioquia (CRUE) | G1: Ejecución Recursos Contigo Antioquia (CRUE)
B2: Fecha | D2: Recursos comprometidos | G2: Fecha | I2: Valor Transferido
B3: 46020 | D3: 1462022598 | G3: 46044 | I3: 207173258
G4: 46101 | I4: 608644587 | L4: =+IF('Ejecución financiera CAS'!B9="crue",'Ejecución financiera CAS'!C9,"")
B8: Valor Total Contrato | D8: =SUM(D3:E4) -> 1462022598 | G8: Total Recursos Entregados | I8: =SUM(I3:J7) -> 815817845
B9: Fecha | C9: Ejecución Financiera Valor + | E9: Sin ejecución | G9: Fecha | H9: Ejecución Financiera Valor + | J9: Sin ejecución | L9: =+C10+C11 -> 169441903 | M9: =+L9*0.08 -> 13555352 | N9: =+M9*0.19 -> 2575516.9 | O9: =+N9+M9 -> 16130869
A10: =IF(B10="","",ROW()-9) -> 1 | B10: 46128 | C10: 27568325 | D10: =+SUM(C10:C11)/$D$8 -> 0.11589554 | E10: =IF(C10=0,0,D3-C10) -> 1434454273 | G10: 12/08/2025 | H10: =+C10 -> 27568325 | I10: =SUM(H10:H11)/$I$8 -> 0.20769575 | J10: =IF(H10=0,"",I8-H10) -> 788249520
A11: =IF(B11="","",ROW()-9) -> 2 | B11: 46129 | C11: 141873578 | E11: =IF(C11=0,0,E10-C11) -> 1292580695 | G11: 02/09/2025 | H11: =+C11 -> 141873578 | J11: =IF(H11=0,"",J10-H11) -> 646375942 | L11: 45786710
A12: =IF(B12="","",ROW()-9) -> 3 | B12: 46155 | C12: 45786710 | E12: =IF(C12=0,0,E11-C12) -> 1246793985 | G12: 46155 | H12: =+C12 -> 45786710 | J12: =IF(H12=0,"",J11-H12) -> 600589232 | L12: 16130869
A13: =IF(B13="","",ROW()-9) -> 4 | B13: 46155 | C13: 16130869 | E13: =IF(C13=0,0,E12-C13) -> 1230663116 | G13: 46155 | H13: =+C13 -> 16130869 | J13: =IF(H13=0,"",J12-H13) -> 584458363 | L13: 40613589
A14: =IF(B14="","",ROW()-9) | E14: =IF(C14=0,0,E13-C14) -> 0 | G14: =IF(B14="","",+B14) | H14: =+C14 -> 0 | J14: =IF(H14=0,"",J13-H14) | L14: 4358895
A15: =IF(B15="","",ROW()-9) | E15: =IF(C15=0,0,E14-C15) -> 0 | G15: =IF(B15="","",+B15) | H15: =+C15 -> 0 | J15: =IF(H15=0,"",J14-H15) | L15: =SUM(L11:L14) -> 106890063
A16: =IF(B16="","",ROW()-9) | E16: =IF(C16=0,0,E15-C16) -> 0 | G16: =IF(B16="","",+B16) | H16: =+C16 -> 0 | J16: =IF(H16=0,"",J15-H16)
A17: =IF(B17="","",ROW()-9) | E17: =IF(C17=0,0,E16-C17) -> 0 | G17: =IF(B17="","",+B17) | H17: =+C17 -> 0 | J17: =IF(H17=0,"",J16-H17)
A18: =IF(B18="","",ROW()-9) | E18: =IF(C18=0,0,E17-C18) -> 0 | G18: =IF(B18="","",+B18) | H18: =+C18 -> 0 | J18: =IF(H18=0,"",J17-H18)
A19: =IF(B19="","",ROW()-9) | E19: =IF(C19=0,0,E18-C19) -> 0 | G19: =IF(B19="","",+B19) | H19: =+C19 -> 0 | J19: =IF(H19=0,"",J18-H19)
A20: =IF(B20="","",ROW()-9) | E20: =IF(C20=0,0,E19-C20) -> 0 | G20: =IF(B20="","",+B20) | H20: =+C20 -> 0 | J20: =IF(H20=0,"",J19-H20)
A21: =IF(B21="","",ROW()-9) | E21: =IF(C21=0,0,E20-C21) -> 0 | G21: =IF(B21="","",+B21) | H21: =+C21 -> 0 | J21: =IF(H21=0,"",J20-H21)
A22: =IF(B22="","",ROW()-9) | E22: =IF(C22=0,0,E21-C22) -> 0 | G22: =IF(B22="","",+B22) | H22: =+C22 -> 0 | J22: =IF(H22=0,"",J21-H22)
A23: =IF(B23="","",ROW()-9) | E23: =IF(C23=0,0,E22-C23) -> 0 | G23: =IF(B23="","",+B23) | H23: =+C23 -> 0 | J23: =IF(H23=0,"",J22-H23)
A24: =IF(B24="","",ROW()-9) | E24: =IF(C24=0,0,E23-C24) -> 0 | G24: =IF(B24="","",+B24) | H24: =+C24 -> 0 | J24: =IF(H24=0,"",J23-H24)
A25: =IF(B25="","",ROW()-9) | E25: =IF(C25=0,0,E24-C25) -> 0 | G25: =IF(B25="","",+B25) | H25: =+C25 -> 0 | J25: =IF(H25=0,"",J24-H25)
A26: =IF(B26="","",ROW()-9) | E26: =IF(C26=0,0,E25-C26) -> 0 | G26: =IF(B26="","",+B26) | H26: =+C26 -> 0 | J26: =IF(H26=0,"",J25-H26)
A27: =IF(B27="","",ROW()-9) | E27: =IF(C27=0,0,E26-C27) -> 0 | G27: =IF(B27="","",+B27) | H27: =+C27 -> 0 | J27: =IF(H27=0,"",J26-H27)
... A33: =IF(B33="","",ROW()-9) | E33: =IF(C33=0,0,E32-C33) -> 0 | G33: =IF(B33="","",+B33) | H33: =+C33 -> 0 | J33: =IF(H33=0,"",J32-H33)
B34: Total Ejecutado | C34: =SUM(C10:C33) -> 231359482 | D34: =1-D10 -> 0.88410446 | E34: =+D8-C34 -> 1230663116 | G34: Total Ejecutado | H34: =SUM(H10:H33) -> 231359482 | I34: =1-I10 -> 0.79230425 | J34: =+I8-H34 -> 584458363
B37: 45757 | D37: 26000000000
G39: Fecha | H39: Ejecución Financiera Fondo GobAnt + IDEA (Otrosí CRUE) | J39: Sin ejecución
G40: 46020 | H40: 1462022598 | I40: =SUM(H41:H46)/$J$40 -> 0.55800632 | J40: =+H40 -> 1462022598
G41: 46044 | H41: 207173258 | J41: =+J40-H41 -> 1254849340
G42: 46101 | H42: 608644587 | J42: =+J41-H42 -> 646204753
J43: =+J42-H43 -> 646204753
J44: =+J43-H44 -> 646204753
J45: =+J44-H45 -> 646204753
J46: =+J45-H46 -> 646204753

Sheet Ejecución Financiera CAS 1
B1: Fecha | C1: Ejecución Financiera Fondo GobAnt + IDEA (CAS) | E1: Sin ejecución | G1: Fecha | H1: Ejecución Financiera Fondo GobAnt + IDEA (Otrosí CRUE) | J1: Sin ejecución
B2: 45757 | C2: 27300000000 | D2: =SUM(C3:C8)/$C$2 -> 0.70695971 | E2: =+C2 -> 27300000000 | G2: 46020 | H2: 1462022598 | I2: =SUM(H3:H8)/$H$2 -> 0.55800632 | J2: =+H2 -> 1462022598
B3: 45594 | C3: 5000000000 | E3: =IF(C3="","",E2-C3) -> 22300000000 | G3: 46044 | H3: 207173258 | J3: =+J2-H3 -> 1254849340
B4: 45595 | C4: 1300000000 | E4: =IF(C4="","",E3-C4) -> 21000000000 | G4: 46101 | H4: 608644587 | J4: =+J3-H4 -> 646204753
B5: 46001 | C5: 6000000000 | E5: =IF(C5="","",E4-C5) -> 15000000000 | J5: =+J4-H5 -> 646204753
B6: 46118 | C6: 7000000000 | E6: =IF(C6="","",E5-C6) -> 8000000000 | J6: =+J5-H6 -> 646204753
E7: =IF(C7="","",E6-C7) | J7: =+J6-H7 -> 646204753
E8: =IF(C8="","",E7-C8) | J8: =+J7-H8 -> 646204753
B12: Fecha | C12: Ejecución Financiera Fondo GobAnt | E12: Sin ejecución
B13: 45757 | C13: 26000000000 | D13: =SUM(C14:C18)/$C$2 -> 0.65934066 | E13: =+C13 -> 26000000000
B14: 45594 | C14: 5000000000 | E14: =IF(C14="","",E13-C14) -> 21000000000
B15: 46001 | C15: 6000000000 | E15: =IF(C15="","",E14-C15) -> 15000000000
B16: 46118 | C16: 7000000000 | E16: =IF(C16="","",E15-C16) -> 8000000000
E17: =IF(C17="","",E16-C17)
E18: =IF(C18="","",E17-C18)
B23: Fecha | C23: Ejecución Financiera | E23: Sin ejecución
B24: 45757 | C24: 5000000000 | D24: =SUM(C25:C34)/$C$24 -> 0.97764798 | E24: =+C24 -> 5000000000
A25: 1 | B25: 45881 | C25: 2200000000 | E25: =IF(C25=0,0,E24-C25) -> 2800000000
A26: 2 | B26: 45902 | C26: 998095000 | E26: =IF(C26=0,0,E25-C26) -> 1801905000
A27: 3 | B27: 45915 | C27: 190754739 | E27: =IF(C27=0,0,E26-C27) -> 1611150261
A28: 4 | B28: 45940 | C28: 13650000 | E28: =IF(C28=0,0,E27-C28) -> 1597500261
A29: 5 | B29: 45945 | C29: 95018644 | E29: =IF(C29=0,0,E28-C29) -> 1502481617
A30: 6 | B30: 45947 | C30: 730635725 | E30: =IF(C30=0,0,E29-C30) -> 771845892
A31: 7 | B31: 45947 | C31: 211478886 | E31: =IF(C31=0,0,E30-C31) -> 560367006
A32: 8 | B32: 45985 | C32: 13650000 | E32: =IF(C32=0,0,E31-C32) -> 546717006
A33: 9 | B33: 45985 | C33: 70856001 | E33: =IF(C33=0,0,E32-C33) -> 475861005
A34: 10 | B34: 45985 | C34: 364100919 | E34: =IF(C34=0,0,E33-C34) -> 111760086
E35: =IF(C35=0,0,E34-C35) -> 0
B36: Total Ejecutado | C36: =SUM(C25:C35) -> 4888239914 | D36: =1-D24 -> 0.022352017 | E36: =+C24-C36 -> 111760086
B40: Fecha | C40: Ejecución Financiera | E40: Sin ejecución
B41: 45985 | C41: =+E34 -> 111760086 | D41: =+SUM(C43:C71)/E42 -> 0.99993741 | E41: =+C41 -> 111760086
B42: 46001 | C42: 6000000000 | E42: =+E41+C42 -> 6111760086
B43: 02/12/2025 | C43: 13650000 | E43: =IF(C43=0,0,E42-C43) -> 6098110086
B44: 02/12/2025 | C44: 1095953586 | E44: =IF(C44=0,0,E43-C44) -> 5002156500
B45: 03/12/2025 | C45: 1299480 | E45: =IF(C45=0,0,E44-C45) -> 5000857020
B46: 03/12/2025 | C46: 262400529 | E46: =IF(C46=0,0,E45-C46) -> 4738456491
B47: 16/01/2026 | C47: 1539588229 | E47: =IF(C47=0,0,E46-C47) -> 3198868262
B48: 19/01/2026 | C48: 105634262 | E48: =IF(C48=0,0,E47-C48) -> 3093234000
B49: 19/01/2026 | C49: 378854365 | E49: =IF(C49=0,0,E48-C49) -> 2714379635
B50: 16/01/2026 | C50: 13650000 | E50: =IF(C50=0,0,E49-C50) -> 2700729635
...

Sheet Avance mensual Conv IDEA
A1: Fecha informe | B1: # | C1: Ejecución | D1: Total informes | E1: 38
A2: 45626 | B2: 1 | C2: =+B2/$E$1 -> 0.026315789
A3: 45657 | B3: 2 | C3: =+B3/$E$1 -> 0.052631579
A4: 45688 | B4: 3 | C4: =+B4/$E$1 -> 0.078947368
A5: 45716 | B5: 4 | C5: =+B5/$E$1 -> 0.10526316
A6: 45747 | B6: 5 | C6: =+B6/$E$1 -> 0.13157895
A7: 45777 | B7: 6 | C7: =+B7/$E$1 -> 0.15789474
A8: 45808 | B8: 7 | C8: =+B8/$E$1 -> 0.18421053
A9: 45838 | B9: 8 | C9: =+B9/$E$1 -> 0.21052632
A10: 45869 | B10: 9 | C10: =+B10/$E$1 -> 0.23684211
A11: 45900 | B11: 10 | C11: =+B11/$E$1 -> 0.26315789
A12: 45930 | B12: 11 | C12: =+B12/$E$1 -> 0.28947368
A13: 45961 | B13: 12 | C13: =+B13/$E$1 -> 0.31578947
... A21: 46203 | B21: 20 | C21: =+B21/$E$1 -> 0.52631579
A22: 46234 | B22: 21 | C22: =+B22/$E$1 -> 0.55263158 | E22: =+C22-C19 -> 0.078947368
A23: 46265 | B23: 22 | C23: =+B23/$E$1 -> 0.57894737
A24: 46295 | B24: 23 | C24: =+B24/$E$1 -> 0.60526316
A25: 46326 | B25: 24 | C25: =+B25/$E$1 -> 0.63157895
A26: 46356 | B26: 25 | C26: =+B26/$E$1 -> 0.65789474
A27: 46387 | B27: 26 | C27: =+B27/$E$1 -> 0.68421053
A28: 46418 | B28: 27 | C28: =+B28/$E$1 -> 0.71052632
A29: 46446 | B29: 28 | C29: =+B29/$E$1 -> 0.73684211
A30: 46477 | B30: 29 | C30: =+B30/$E$1 -> 0.76315789
A31: 46507 | B31: 30 | C31: =+B31/$E$1 -> 0.78947368
A32: 46538 | B32: 31 | C32: =+B32/$E$1 -> 0.81578947
A33: 46568 | B33: 32 | C33: =+B33/$E$1 -> 0.84210526
A34: 46599 | B34: 33 | C34: =+B34/$E$1 -> 0.86842105
... A39: 46752 | B39: 38 | C39: =+B39/$E$1 -> 1

Sheet Hoja1
C1: Recursos vigencia 2026
D2: 7000000000
C4: Fecha | D4: Recuros Transferidos
C5: 46171 | D5: 1817086974
C6: 46191 | D6: 526978224
C7: 46220 | D7: 526978224
C8: Total | D8: =SUM(D5:D7) -> 2871043422
C10: Recuros por transferir:
D11: =7000000000-SUM(D5:D7) -> 4128956578
